<?xml version="1.0" encoding="utf-8"?>
<!-- This URDF was automatically created by SolidWorks to URDF Exporter! Originally created by Stephen Brawner (brawner@gmail.com) 
     Commit Version: 1.6.0-4-g7f85cfe  Build Version: 1.6.7995.38578
     For more information, please see http://wiki.ros.org/sw_urdf_exporter -->
<robot
  name="robotbase_description">
  <link
    name="base_link">
    <inertial>
      <origin
        xyz="-0.054826 0.00057958 0.098078"
        rpy="0 0 0" />
      <mass
        value="1.694" />
      <inertia
        ixx="0.0059056"
        ixy="-9.3677E-07"
        ixz="2.9127E-06"
        iyy="0.0064323"
        iyz="2.7055E-06"
        izz="0.012007" />
    </inertial>
    <visual>
      <origin
        xyz="0 0 0"
        rpy="0 0 0" />
      <geometry>
        <mesh
          filename="package://robotbase_description/meshes/base_link.STL" />
      </geometry>
      <material
        name="">
        <color
          rgba="0.79216 0.81961 0.93333 1" />
      </material>
    </visual>
    <collision>
      <origin
        xyz="0 0 0"
        rpy="0 0 0" />
      <geometry>
        <mesh
          filename="package://robotbase_description/meshes/base_link.STL" />
      </geometry>
    </collision>
  </link>
  <link
    name="link_left">
    <inertial>
      <origin
        xyz="0 0 -0.01"
        rpy="0 0 0" />
      <mass
        value="0.15096" />
      <inertia
        ixx="9.6648E-05"
        ixy="1.0519E-21"
        ixz="1.0764E-21"
        iyy="9.6648E-05"
        iyz="3.3501E-23"
        izz="0.00018295" />
    </inertial>
    <visual>
      <origin
        xyz="0 0 0"
        rpy="0 0 0" />
      <geometry>
        <mesh
          filename="package://robotbase_description/meshes/link_left.STL" />
      </geometry>
      <material
        name="">
        <color
          rgba="0.79216 0.81961 0.93333 1" />
      </material>
    </visual>
    <collision>
      <origin
        xyz="0 0 0"
        rpy="0 0 0" />
      <geometry>
        <mesh
          filename="package://robotbase_description/meshes/link_left.STL" />
      </geometry>
    </collision>
  </link>
  <joint
    name="joint_left"
    type="continuous">
    <origin
      xyz="0.000764 0.125 -0.0232"
      rpy="1.5708 0 3.1416" />
    <parent
      link="base_link" />
    <child
      link="link_left" />
    <axis
      xyz="0 0 -1" />
    <limit
      effort="2"
      velocity="0.5" />
  </joint>
  <link
    name="link_right">
    <inertial>
      <origin
        xyz="0 0 -0.01"
        rpy="0 0 0" />
      <mass
        value="0.15096" />
      <inertia
        ixx="9.6648E-05"
        ixy="-1.0519E-21"
        ixz="-5.294E-23"
        iyy="9.6648E-05"
        iyz="-3.3501E-23"
        izz="0.00018295" />
    </inertial>
    <visual>
      <origin
        xyz="0 0 0"
        rpy="0 0 0" />
      <geometry>
        <mesh
          filename="package://robotbase_description/meshes/link_right.STL" />
      </geometry>
      <material
        name="">
        <color
          rgba="0.79216 0.81961 0.93333 1" />
      </material>
    </visual>
    <collision>
      <origin
        xyz="0 0 0"
        rpy="0 0 0" />
      <geometry>
        <mesh
          filename="package://robotbase_description/meshes/link_right.STL" />
      </geometry>
    </collision>
  </link>
  <joint
    name="joint_right"
    type="continuous">
    <origin
      xyz="0.000764 -0.125 -0.0232"
      rpy="1.5708 0 0" />
    <parent
      link="base_link" />
    <child
      link="link_right" />
    <axis
      xyz="0 0 -1" />
    <limit
      effort="2"
      velocity="0.5" />
  </joint>
</robot>